<?xml version="1.0"?>
<robot xmlns:xacro="http://www.ros.org/wiki/xacro" >

    <xacro:include filename="inertial_macros.xacro"/>
    
    <material name="white">
        <color rgba="1 1 1 1" />
    </material>

    <material name="orange">
        <color rgba="1 0.3 0.1 1" />
    </material>

    <material name="blue">
        <color rgba="0.2 0.2 1 1" />
    </material>

    <material name="black">
        <color rgba="0 0 0 1" />
    </material>

    <!-- base_link -->
    <link name="base_link">

    </link>

    <!--chasis link-->
    <joint name="chassis_joint" type="fixed">
        <parent link="base_link" />
        <child link="chassis" />
        <origin xyz="-0.015 0 0"/>
    </joint>

    <link name="chassis">
        <visual>
            <origin xyz="0.095 0 0.01"/>
            <geometry>
                <box size="0.19 0.15 0.04"/>
            </geometry>
            <material name="white"/>
        </visual>
        <collision>
            <origin xyz="0.095 0 0.01"/>
            <geometry>
                <box size="0.19 0.15 0.04"/>
            </geometry>
        </collision>
        <xacro:inertial_box mass="0.5" x="0.19" y="0.15" z="0.04">
            <origin xyz ="0.095 0 0.01" rpy="0.0 0.0 0.0"/>
        </xacro:inertial_box>    
    </link>

    <!-- LEFT WHEEL LINK -->

    <joint name="left_wheel" type="continuous">
        <parent link="base_link"/>
        <child link="left_wheel"/> 
        <origin xyz="0.0 0.088 0.0" rpy=" -${pi/2} 0.0 0.0"/>
        <axis xyz="0.0 0.0 1"/>     
    </joint>

    <link name="left_wheel">
    <visual>
        <geometry>
            <cylinder radius="0.0325" length="0.025"/>
        </geometry>
        <material name="blue"/>           
    </visual>
    <collision>
        <geometry>
            <cylinder radius="0.0325" length="0.025"/>
        </geometry>        
    </collision>
    <xacro:inertial_cylinder mass="0.1" length="0.04" radius="0.05">
        <origin xyz="0 0 0" rpy="0 0 0"/>
    </xacro:inertial_cylinder>    
    </link>

<!-- RIGHT WHEEL LINK -->

    <joint name="right_wheel" type="continuous">
        <parent link="base_link"/>
        <child link="right_wheel"/> 
        <origin xyz="0.0 -0.088 0.0" rpy="${pi/2} 0.0 0.0"/>
        <axis xyz="0.0 0.0 -1"/>     
    </joint>

    <link name="right_wheel">
    <visual>
        <geometry>
            <cylinder radius="0.0325" length="0.025"/>
        </geometry>
        <material name="blue"/>         
    </visual>
    <collision>
        <geometry>
            <cylinder radius="0.0325" length="0.025"/>
        </geometry>       
    </collision>
    <xacro:inertial_cylinder mass="0.1" length="0.04" radius="0.05">
        <origin xyz="0 0 0" rpy="0 0 0"/>
    </xacro:inertial_cylinder>  
    </link>

    <!-- CASTER WHEEL LINK -->

    <joint name="caster_wheel" type="fixed">
        <parent link="chassis"/>
        <child link="caster_wheel"/> 
        <origin xyz="0.16 0 -0.02"/>   
    </joint>

    <link name="caster_wheel">
    <visual>
        <geometry>
            <sphere radius="0.02"/>
        </geometry>
        <material name="orange"/>            
    </visual>
    <collision>
        <geometry>
            <sphere radius="0.02"/>
        </geometry>           
    </collision>
    <xacro:inertial_sphere mass="0.1" radius="0.05">
        <origin xyz="0 0 0" rpy="0 0 0"/>
    </xacro:inertial_sphere> 
    </link>
</robot>